Traceback (most recent call last):
  File "/opt/hostedtoolcache/Python/3.12.7/x64/lib/python3.12/site-packages/jupyter_cache/executors/utils.py", line 58, in single_nb_execution
    executenb(
  File "/opt/hostedtoolcache/Python/3.12.7/x64/lib/python3.12/site-packages/nbclient/client.py", line 1314, in execute
    return NotebookClient(nb=nb, resources=resources, km=km, **kwargs).execute()
           ^^^^^^^^^^^^^^^^^^^^^^^^^^^^^^^^^^^^^^^^^^^^^^^^^^^^^^^^^^^^^^^^^^^^^
  File "/opt/hostedtoolcache/Python/3.12.7/x64/lib/python3.12/site-packages/jupyter_core/utils/__init__.py", line 165, in wrapped
    return loop.run_until_complete(inner)
           ^^^^^^^^^^^^^^^^^^^^^^^^^^^^^^
  File "/opt/hostedtoolcache/Python/3.12.7/x64/lib/python3.12/asyncio/base_events.py", line 687, in run_until_complete
    return future.result()
           ^^^^^^^^^^^^^^^
  File "/opt/hostedtoolcache/Python/3.12.7/x64/lib/python3.12/site-packages/nbclient/client.py", line 709, in async_execute
    await self.async_execute_cell(
  File "/opt/hostedtoolcache/Python/3.12.7/x64/lib/python3.12/site-packages/nbclient/client.py", line 1062, in async_execute_cell
    await self._check_raise_for_error(cell, cell_index, exec_reply)
  File "/opt/hostedtoolcache/Python/3.12.7/x64/lib/python3.12/site-packages/nbclient/client.py", line 918, in _check_raise_for_error
    raise CellExecutionError.from_cell_and_msg(cell, exec_reply_content)
nbclient.exceptions.CellExecutionError: An error occurred while executing the following cell:
------------------
import pvlib

df, meta = pvlib.iotools.get_bsrn(
    station='CAB',  # three letter code for the Cabauw station
    start=pd.Timestamp(2018,6,1),
    end=pd.Timestamp(2018,7,14),
    username=bsrn_username,  # replace with your own username
    password=bsrn_password,  # replace with your own password
)

show(df.head(), scrollX=True, scrollCollapse=True, paging=False, maxColumns=100, dom="tpr")
------------------

----- stderr -----
/opt/hostedtoolcache/Python/3.12.7/x64/lib/python3.12/site-packages/pvlib/iotools/bsrn.py:162: FutureWarning: 'M' is deprecated and will be removed in a future version, please use 'ME' instead.
  filenames = pd.date_range(
------------------

[0;31m---------------------------------------------------------------------------[0m
[0;31merror_perm[0m                                Traceback (most recent call last)
File [0;32m/opt/hostedtoolcache/Python/3.12.7/x64/lib/python3.12/site-packages/pvlib/iotools/bsrn.py:170[0m, in [0;36mget_bsrn[0;34m(station, start, end, username, password, logical_records, save_path)[0m
[1;32m    169[0m [38;5;28;01mtry[39;00m:
[0;32m--> 170[0m     [43mftp[49m[38;5;241;43m.[39;49m[43mcwd[49m[43m([49m[38;5;124;43mf[39;49m[38;5;124;43m'[39;49m[38;5;124;43m/[39;49m[38;5;132;43;01m{[39;49;00m[43mstation[49m[38;5;132;43;01m}[39;49;00m[38;5;124;43m'[39;49m[43m)[49m
[1;32m    171[0m [38;5;28;01mexcept[39;00m ftplib[38;5;241m.[39merror_perm [38;5;28;01mas[39;00m e:

File [0;32m/opt/hostedtoolcache/Python/3.12.7/x64/lib/python3.12/ftplib.py:619[0m, in [0;36mFTP.cwd[0;34m(self, dirname)[0m
[1;32m    618[0m cmd [38;5;241m=[39m [38;5;124m'[39m[38;5;124mCWD [39m[38;5;124m'[39m [38;5;241m+[39m dirname
[0;32m--> 619[0m [38;5;28;01mreturn[39;00m [38;5;28;43mself[39;49m[38;5;241;43m.[39;49m[43mvoidcmd[49m[43m([49m[43mcmd[49m[43m)[49m

File [0;32m/opt/hostedtoolcache/Python/3.12.7/x64/lib/python3.12/ftplib.py:286[0m, in [0;36mFTP.voidcmd[0;34m(self, cmd)[0m
[1;32m    285[0m [38;5;28mself[39m[38;5;241m.[39mputcmd(cmd)
[0;32m--> 286[0m [38;5;28;01mreturn[39;00m [38;5;28;43mself[39;49m[38;5;241;43m.[39;49m[43mvoidresp[49m[43m([49m[43m)[49m

File [0;32m/opt/hostedtoolcache/Python/3.12.7/x64/lib/python3.12/ftplib.py:259[0m, in [0;36mFTP.voidresp[0;34m(self)[0m
[1;32m    258[0m [38;5;250m[39m[38;5;124;03m"""Expect a response beginning with '2'."""[39;00m
[0;32m--> 259[0m resp [38;5;241m=[39m [38;5;28;43mself[39;49m[38;5;241;43m.[39;49m[43mgetresp[49m[43m([49m[43m)[49m
[1;32m    260[0m [38;5;28;01mif[39;00m resp[:[38;5;241m1[39m] [38;5;241m!=[39m [38;5;124m'[39m[38;5;124m2[39m[38;5;124m'[39m:

File [0;32m/opt/hostedtoolcache/Python/3.12.7/x64/lib/python3.12/ftplib.py:254[0m, in [0;36mFTP.getresp[0;34m(self)[0m
[1;32m    253[0m [38;5;28;01mif[39;00m c [38;5;241m==[39m [38;5;124m'[39m[38;5;124m5[39m[38;5;124m'[39m:
[0;32m--> 254[0m     [38;5;28;01mraise[39;00m error_perm(resp)
[1;32m    255[0m [38;5;28;01mraise[39;00m error_proto(resp)

[0;31merror_perm[0m: 530 Please login with USER and PASS.

The above exception was the direct cause of the following exception:

[0;31mKeyError[0m                                  Traceback (most recent call last)
Cell [0;32mIn[4], line 3[0m
[1;32m      1[0m [38;5;28;01mimport[39;00m [38;5;21;01mpvlib[39;00m
[0;32m----> 3[0m df, meta [38;5;241m=[39m [43mpvlib[49m[38;5;241;43m.[39;49m[43miotools[49m[38;5;241;43m.[39;49m[43mget_bsrn[49m[43m([49m
[1;32m      4[0m [43m    [49m[43mstation[49m[38;5;241;43m=[39;49m[38;5;124;43m'[39;49m[38;5;124;43mCAB[39;49m[38;5;124;43m'[39;49m[43m,[49m[43m  [49m[38;5;66;43;03m# three letter code for the Cabauw station[39;49;00m
[1;32m      5[0m [43m    [49m[43mstart[49m[38;5;241;43m=[39;49m[43mpd[49m[38;5;241;43m.[39;49m[43mTimestamp[49m[43m([49m[38;5;241;43m2018[39;49m[43m,[49m[38;5;241;43m6[39;49m[43m,[49m[38;5;241;43m1[39;49m[43m)[49m[43m,[49m
[1;32m      6[0m [43m    [49m[43mend[49m[38;5;241;43m=[39;49m[43mpd[49m[38;5;241;43m.[39;49m[43mTimestamp[49m[43m([49m[38;5;241;43m2018[39;49m[43m,[49m[38;5;241;43m7[39;49m[43m,[49m[38;5;241;43m14[39;49m[43m)[49m[43m,[49m
[1;32m      7[0m [43m    [49m[43musername[49m[38;5;241;43m=[39;49m[43mbsrn_username[49m[43m,[49m[43m  [49m[38;5;66;43;03m# replace with your own username[39;49;00m
[1;32m      8[0m [43m    [49m[43mpassword[49m[38;5;241;43m=[39;49m[43mbsrn_password[49m[43m,[49m[43m  [49m[38;5;66;43;03m# replace with your own password[39;49;00m
[1;32m      9[0m [43m)[49m
[1;32m     11[0m show(df[38;5;241m.[39mhead(), scrollX[38;5;241m=[39m[38;5;28;01mTrue[39;00m, scrollCollapse[38;5;241m=[39m[38;5;28;01mTrue[39;00m, paging[38;5;241m=[39m[38;5;28;01mFalse[39;00m, maxColumns[38;5;241m=[39m[38;5;241m100[39m, dom[38;5;241m=[39m[38;5;124m"[39m[38;5;124mtpr[39m[38;5;124m"[39m)

File [0;32m/opt/hostedtoolcache/Python/3.12.7/x64/lib/python3.12/site-packages/pvlib/iotools/bsrn.py:172[0m, in [0;36mget_bsrn[0;34m(station, start, end, username, password, logical_records, save_path)[0m
[1;32m    170[0m     ftp[38;5;241m.[39mcwd([38;5;124mf[39m[38;5;124m'[39m[38;5;124m/[39m[38;5;132;01m{[39;00mstation[38;5;132;01m}[39;00m[38;5;124m'[39m)
[1;32m    171[0m [38;5;28;01mexcept[39;00m ftplib[38;5;241m.[39merror_perm [38;5;28;01mas[39;00m e:
[0;32m--> 172[0m     [38;5;28;01mraise[39;00m [38;5;167;01mKeyError[39;00m([38;5;124m'[39m[38;5;124mStation sub-directory does not exist. Specified [39m[38;5;124m'[39m
[1;32m    173[0m                    [38;5;124m'[39m[38;5;124mstation is probably not a proper three letter [39m[38;5;124m'[39m
[1;32m    174[0m                    [38;5;124m'[39m[38;5;124mstation abbreviation.[39m[38;5;124m'[39m) [38;5;28;01mfrom[39;00m [38;5;21;01me[39;00m
[1;32m    175[0m dfs [38;5;241m=[39m []  [38;5;66;03m# Initialize list for monthly dataframes[39;00m
[1;32m    176[0m non_existing_files [38;5;241m=[39m []  [38;5;66;03m# Initilize list of files that were not found[39;00m

[0;31mKeyError[0m: 'Station sub-directory does not exist. Specified station is probably not a proper three letter station abbreviation.'

